{"trial_id": "00", "hyperparameters": {"space": [{"class_name": "Choice", "config": {"name": "rate_1", "default": 0.25, "conditions": [], "values": [0.25, 0.5, 0.75], "ordered": true}}, {"class_name": "Choice", "config": {"name": "rate_2", "default": 0.25, "conditions": [], "values": [0.25, 0.5, 0.75], "ordered": true}}, {"class_name": "Choice", "config": {"name": "rate_3", "default": 0.25, "conditions": [], "values": [0.25, 0.5, 0.75], "ordered": true}}, {"class_name": "Choice", "config": {"name": "rate_4", "default": 0.25, "conditions": [], "values": [0.25, 0.5, 0.75], "ordered": true}}, {"class_name": "Choice", "config": {"name": "rate_5", "default": 0.25, "conditions": [], "values": [0.25, 0.5, 0.75], "ordered": true}}], "values": {"rate_1": 0.5, "rate_2": 0.25, "rate_3": 0.25, "rate_4": 0.75, "rate_5": 0.5}}, "metrics": {"metrics": {}}, "score": null, "best_step": 0, "status": "FAILED", "message": "Traceback (most recent call last):\n  File \"c:\\Users\\seand\\.conda\\envs\\Final_project_keras_tuner\\lib\\site-packages\\keras_tuner\\src\\engine\\base_tuner.py\", line 274, in _try_run_and_update_trial\n    self._run_and_update_trial(trial, *fit_args, **fit_kwargs)\n  File \"c:\\Users\\seand\\.conda\\envs\\Final_project_keras_tuner\\lib\\site-packages\\keras_tuner\\src\\engine\\base_tuner.py\", line 239, in _run_and_update_trial\n    results = self.run_trial(trial, *fit_args, **fit_kwargs)\n  File \"c:\\Users\\seand\\.conda\\envs\\Final_project_keras_tuner\\lib\\site-packages\\keras_tuner\\src\\engine\\tuner.py\", line 314, in run_trial\n    obj_value = self._build_and_fit_model(trial, *args, **copied_kwargs)\n  File \"c:\\Users\\seand\\.conda\\envs\\Final_project_keras_tuner\\lib\\site-packages\\keras_tuner\\src\\engine\\tuner.py\", line 233, in _build_and_fit_model\n    results = self.hypermodel.fit(hp, model, *args, **kwargs)\n  File \"c:\\Users\\seand\\.conda\\envs\\Final_project_keras_tuner\\lib\\site-packages\\keras_tuner\\src\\engine\\hypermodel.py\", line 149, in fit\n    return model.fit(*args, **kwargs)\n  File \"c:\\Users\\seand\\.conda\\envs\\Final_project_keras_tuner\\lib\\site-packages\\keras\\utils\\traceback_utils.py\", line 70, in error_handler\n    raise e.with_traceback(filtered_tb) from None\n  File \"c:\\Users\\seand\\.conda\\envs\\Final_project_keras_tuner\\lib\\site-packages\\tensorflow\\python\\eager\\execute.py\", line 54, in quick_execute\n    tensors = pywrap_tfe.TFE_Py_Execute(ctx._handle, device_name, op_name,\ntensorflow.python.framework.errors_impl.UnknownError: {{function_node __wrapped__MergeV2Checkpoints_device_/job:localhost/replica:0/task:0/device:CPU:0}} Failed to create a NewWriteableFile: saved models/2. model 2 dropout/hyper p/simple_model_Relu_with_dropout_hyper_p_v2\\trial_00\\checkpoint.index : Access is denied.\r\n; Input/output error [Op:MergeV2Checkpoints]\n"}